[2024-07-09T17:29:56.254+0000] {taskinstance.py:1979} INFO - Dependencies all met for dep_context=non-requeueable deps ti=<TaskInstance: pesquisa_industrial_anual_empresas.workspace manual__2024-07-09T17:22:24.727774+00:00 [queued]>
[2024-07-09T17:29:56.261+0000] {taskinstance.py:1979} INFO - Dependencies all met for dep_context=requeueable deps ti=<TaskInstance: pesquisa_industrial_anual_empresas.workspace manual__2024-07-09T17:22:24.727774+00:00 [queued]>
[2024-07-09T17:29:56.262+0000] {taskinstance.py:2193} INFO - Starting attempt 5 of 5
[2024-07-09T17:29:56.277+0000] {taskinstance.py:2217} INFO - Executing <Task(PapermillOperator): workspace> on 2024-07-09 17:22:24.727774+00:00
[2024-07-09T17:29:56.284+0000] {standard_task_runner.py:60} INFO - Started process 2152 to run task
[2024-07-09T17:29:56.286+0000] {standard_task_runner.py:87} INFO - Running: ['***', 'tasks', 'run', 'pesquisa_industrial_anual_empresas', 'workspace', 'manual__2024-07-09T17:22:24.727774+00:00', '--job-id', '11', '--raw', '--subdir', 'DAGS_FOLDER/pesquisa_industrial_anual_empresas/dags.py', '--cfg-path', '/tmp/tmpuf1azi45']
[2024-07-09T17:29:56.289+0000] {standard_task_runner.py:88} INFO - Job 11: Subtask workspace
[2024-07-09T17:29:56.339+0000] {task_command.py:423} INFO - Running <TaskInstance: pesquisa_industrial_anual_empresas.workspace manual__2024-07-09T17:22:24.727774+00:00 [running]> on host 049690d4da25
[2024-07-09T17:29:56.408+0000] {taskinstance.py:2513} INFO - Exporting env vars: AIRFLOW_CTX_DAG_EMAIL='observatorio@sistemafiea.com.br' AIRFLOW_CTX_DAG_OWNER='***' AIRFLOW_CTX_DAG_ID='pesquisa_industrial_anual_empresas' AIRFLOW_CTX_TASK_ID='workspace' AIRFLOW_CTX_EXECUTION_DATE='2024-07-09T17:22:24.727774+00:00' AIRFLOW_CTX_TRY_NUMBER='5' AIRFLOW_CTX_DAG_RUN_ID='manual__2024-07-09T17:22:24.727774+00:00'
[2024-07-09T17:29:56.409+0000] {execute.py:83} INFO - Input Notebook:  /opt/***/dags/pesquisa_industrial_anual_empresas/notebooks/workspace.ipynb
[2024-07-09T17:29:56.410+0000] {execute.py:84} INFO - Output Notebook: /opt/***/dags/resultado/pesquisa_industrial_anual_empresas_workspace_2024-07-09.ipynb
[2024-07-09T17:29:57.659+0000] {clientwrap.py:44} INFO - Executing notebook with kernel: python3
[2024-07-09T17:30:05.965+0000] {taskinstance.py:2731} ERROR - Task failed with exception
Traceback (most recent call last):
  File "/home/airflow/.local/lib/python3.11/site-packages/airflow/models/taskinstance.py", line 444, in _execute_task
    result = _execute_callable(context=context, **execute_callable_kwargs)
             ^^^^^^^^^^^^^^^^^^^^^^^^^^^^^^^^^^^^^^^^^^^^^^^^^^^^^^^^^^^^^
  File "/home/airflow/.local/lib/python3.11/site-packages/airflow/models/taskinstance.py", line 414, in _execute_callable
    return execute_callable(context=context, **execute_callable_kwargs)
           ^^^^^^^^^^^^^^^^^^^^^^^^^^^^^^^^^^^^^^^^^^^^^^^^^^^^^^^^^^^^
  File "/home/airflow/.local/lib/python3.11/site-packages/airflow/providers/papermill/operators/papermill.py", line 118, in execute
    pm.execute_notebook(
  File "/home/airflow/.local/lib/python3.11/site-packages/papermill/execute.py", line 131, in execute_notebook
    raise_for_execution_errors(nb, output_path)
  File "/home/airflow/.local/lib/python3.11/site-packages/papermill/execute.py", line 251, in raise_for_execution_errors
    raise error
papermill.exceptions.PapermillExecutionError: 
---------------------------------------------------------------------------
Exception encountered at "In [4]":
---------------------------------------------------------------------------
AnalysisException                         Traceback (most recent call last)
Cell In[4], line 8
      5 csv_file_path = "/pesquisa_industrial_anual_empresas.csv"
      7 # Leia o arquivo CSV usando PySpark
----> 8 df = spark.read.csv(csv_file_path, header=True, inferSchema=True)
     10 # Mostre o DataFrame
     11 df.show()

File ~/.local/lib/python3.11/site-packages/pyspark/sql/readwriter.py:740, in DataFrameReader.csv(self, path, schema, sep, encoding, quote, escape, comment, header, inferSchema, ignoreLeadingWhiteSpace, ignoreTrailingWhiteSpace, nullValue, nanValue, positiveInf, negativeInf, dateFormat, timestampFormat, maxColumns, maxCharsPerColumn, maxMalformedLogPerPartition, mode, columnNameOfCorruptRecord, multiLine, charToEscapeQuoteEscaping, samplingRatio, enforceSchema, emptyValue, locale, lineSep, pathGlobFilter, recursiveFileLookup, modifiedBefore, modifiedAfter, unescapedQuoteHandling)
    738 if type(path) == list:
    739     assert self._spark._sc._jvm is not None
--> 740     return self._df(self._jreader.csv(self._spark._sc._jvm.PythonUtils.toSeq(path)))
    741 elif isinstance(path, RDD):
    743     def func(iterator):

File ~/.local/lib/python3.11/site-packages/py4j/java_gateway.py:1322, in JavaMember.__call__(self, *args)
   1316 command = proto.CALL_COMMAND_NAME +\
   1317     self.command_header +\
   1318     args_command +\
   1319     proto.END_COMMAND_PART
   1321 answer = self.gateway_client.send_command(command)
-> 1322 return_value = get_return_value(
   1323     answer, self.gateway_client, self.target_id, self.name)
   1325 for temp_arg in temp_args:
   1326     if hasattr(temp_arg, "_detach"):

File ~/.local/lib/python3.11/site-packages/pyspark/errors/exceptions/captured.py:185, in capture_sql_exception.<locals>.deco(*a, **kw)
    181 converted = convert_exception(e.java_exception)
    182 if not isinstance(converted, UnknownException):
    183     # Hide where the exception came from that shows a non-Pythonic
    184     # JVM exception message.
--> 185     raise converted from None
    186 else:
    187     raise

AnalysisException: [PATH_NOT_FOUND] Path does not exist: file:/pesquisa_industrial_anual_empresas.csv.

[2024-07-09T17:30:05.980+0000] {taskinstance.py:1149} INFO - Marking task as FAILED. dag_id=pesquisa_industrial_anual_empresas, task_id=workspace, execution_date=20240709T172224, start_date=20240709T172956, end_date=20240709T173005
[2024-07-09T17:30:06.016+0000] {standard_task_runner.py:107} ERROR - Failed to execute job 11 for task workspace (
---------------------------------------------------------------------------
Exception encountered at "In [4]":
---------------------------------------------------------------------------
AnalysisException                         Traceback (most recent call last)
Cell In[4], line 8
      5 csv_file_path = "/pesquisa_industrial_anual_empresas.csv"
      7 # Leia o arquivo CSV usando PySpark
----> 8 df = spark.read.csv(csv_file_path, header=True, inferSchema=True)
     10 # Mostre o DataFrame
     11 df.show()

File ~/.local/lib/python3.11/site-packages/pyspark/sql/readwriter.py:740, in DataFrameReader.csv(self, path, schema, sep, encoding, quote, escape, comment, header, inferSchema, ignoreLeadingWhiteSpace, ignoreTrailingWhiteSpace, nullValue, nanValue, positiveInf, negativeInf, dateFormat, timestampFormat, maxColumns, maxCharsPerColumn, maxMalformedLogPerPartition, mode, columnNameOfCorruptRecord, multiLine, charToEscapeQuoteEscaping, samplingRatio, enforceSchema, emptyValue, locale, lineSep, pathGlobFilter, recursiveFileLookup, modifiedBefore, modifiedAfter, unescapedQuoteHandling)
    738 if type(path) == list:
    739     assert self._spark._sc._jvm is not None
--> 740     return self._df(self._jreader.csv(self._spark._sc._jvm.PythonUtils.toSeq(path)))
    741 elif isinstance(path, RDD):
    743     def func(iterator):

File ~/.local/lib/python3.11/site-packages/py4j/java_gateway.py:1322, in JavaMember.__call__(self, *args)
   1316 command = proto.CALL_COMMAND_NAME +\
   1317     self.command_header +\
   1318     args_command +\
   1319     proto.END_COMMAND_PART
   1321 answer = self.gateway_client.send_command(command)
-> 1322 return_value = get_return_value(
   1323     answer, self.gateway_client, self.target_id, self.name)
   1325 for temp_arg in temp_args:
   1326     if hasattr(temp_arg, "_detach"):

File ~/.local/lib/python3.11/site-packages/pyspark/errors/exceptions/captured.py:185, in capture_sql_exception.<locals>.deco(*a, **kw)
    181 converted = convert_exception(e.java_exception)
    182 if not isinstance(converted, UnknownException):
    183     # Hide where the exception came from that shows a non-Pythonic
    184     # JVM exception message.
--> 185     raise converted from None
    186 else:
    187     raise

AnalysisException: [PATH_NOT_FOUND] Path does not exist: file:/pesquisa_industrial_anual_empresas.csv.
; 2152)
[2024-07-09T17:30:06.032+0000] {local_task_job_runner.py:234} INFO - Task exited with return code 1
[2024-07-09T17:30:06.056+0000] {taskinstance.py:3312} INFO - 0 downstream tasks scheduled from follow-on schedule check
